==STDERR==
Traceback (most recent call last):
  File "/BIGDATA/ac_shao_tan_1/OSKAR/OSKAR_CASA/data_reduction.py", line 41, in <module>
    casa.run_script_from_file('/BIGDATA/ac_shao_tan_1/OSKAR/OSKAR_CASA/image.py',timeout = 60000)
  File "/BIGDATA/ac_shao_tan_1/OSKAR/python/lib/python2.7/site-packages/drive_casa-0.7.5-py2.7.egg/drivecasa/interface.py", line 286, in run_script_from_file
    error_str)
RuntimeError: Casapy encountered a 'SEVERE' level problem running the script at /BIGDATA/ac_shao_tan_1/OSKAR/OSKAR_CASA/image.py:
*********

*********
Errors are as follows:
2017-08-15 02:50:46     SEVERE  casa::Imager::writeHistory      Caught exception: Error (Resource deadlock avoided) when acquiring lock on /BIGDATA/ac_shao_tan_1/OSKAR/OSKAR_CASA/config/1_-6_0_0.ms/HISTORY/table.lock

2017-08-15 03:03:08,087 [ERROR] [     Thread-614] dfms.drop#execute:1458 Error while executing <BashShellApp oid=1_-16_0/0/3, uid=1_-16_0/0/3> (try 1/1)
Traceback (most recent call last):
  File "/BIGDATA/ac_shao_tan_1/OSKAR/python/lib/python2.7/site-packages/dfms-0.2.0.dev0+unknown-py2.7.egg/dfms/drop.py", line 1453, in execute
    self.run()
  File "/BIGDATA/ac_shao_tan_1/OSKAR/python/lib/python2.7/site-packages/dfms-0.2.0.dev0+unknown-py2.7.egg/dfms/apps/bash_shell_app.py", line 270, in run
    run_bash(self._command + '  %s' % self.uid, self._inputs, self._outputs)
  File "/BIGDATA/ac_shao_tan_1/OSKAR/python/lib/python2.7/site-packages/dfms-0.2.0.dev0+unknown-py2.7.egg/dfms/apps/bash_shell_app.py", line 114, in run_bash
    raise Exception(message)
Exception: Command didn't finish successfully (exit code 1)